
Exception in thread django-main-thread:
Traceback (most recent call last):
  File "/usr/lib/python3.6/threading.py", line 916, in _bootstrap_inner
    self.run()
  File "/usr/lib/python3.6/threading.py", line 864, in run
    self._target(*self._args, **self._kwargs)
  File "/projects/Python/Django/guestbook/venv/lib/python3.6/site-packages/django/utils/autoreload.py", line 54, in wrapper
    fn(*args, **kwargs)
  File "/projects/Python/Django/guestbook/venv/lib/python3.6/site-packages/django/core/management/commands/runserver.py", line 117, in inner_run
    self.check(display_num_errors=True)
  File "/projects/Python/Django/guestbook/venv/lib/python3.6/site-packages/django/core/management/base.py", line 390, in check
    include_deployment_checks=include_deployment_checks,
  File "/projects/Python/Django/guestbook/venv/lib/python3.6/site-packages/django/core/management/base.py", line 377, in _run_checks
    return checks.run_checks(**kwargs)
  File "/projects/Python/Django/guestbook/venv/lib/python3.6/site-packages/django/core/checks/registry.py", line 72, in run_checks
    new_errors = check(app_configs=app_configs)
  File "/projects/Python/Django/guestbook/venv/lib/python3.6/site-packages/django/core/checks/urls.py", line 13, in check_url_config
    return check_resolver(resolver)
  File "/projects/Python/Django/guestbook/venv/lib/python3.6/site-packages/django/core/checks/urls.py", line 23, in check_resolver
    return check_method()
  File "/projects/Python/Django/guestbook/venv/lib/python3.6/site-packages/django/urls/resolvers.py", line 398, in check
    for pattern in self.url_patterns:
  File "/projects/Python/Django/guestbook/venv/lib/python3.6/site-packages/django/utils/functional.py", line 80, in __get__
    res = instance.__dict__[self.name] = self.func(instance)
  File "/projects/Python/Django/guestbook/venv/lib/python3.6/site-packages/django/urls/resolvers.py", line 579, in url_patterns
    patterns = getattr(self.urlconf_module, "urlpatterns", self.urlconf_module)
  File "/projects/Python/Django/guestbook/venv/lib/python3.6/site-packages/django/utils/functional.py", line 80, in __get__
    res = instance.__dict__[self.name] = self.func(instance)
  File "/projects/Python/Django/guestbook/venv/lib/python3.6/site-packages/django/urls/resolvers.py", line 572, in urlconf_module
    return import_module(self.urlconf_name)
  File "/projects/Python/Django/guestbook/venv/lib/python3.6/importlib/__init__.py", line 126, in import_module
    return _bootstrap._gcd_import(name[level:], package, level)
  File "<frozen importlib._bootstrap>", line 994, in _gcd_import
  File "<frozen importlib._bootstrap>", line 971, in _find_and_load
  File "<frozen importlib._bootstrap>", line 955, in _find_and_load_unlocked
  File "<frozen importlib._bootstrap>", line 665, in _load_unlocked
  File "<frozen importlib._bootstrap_external>", line 678, in exec_module
  File "<frozen importlib._bootstrap>", line 219, in _call_with_frames_removed
  File "/projects/Python/Django/guestbook/main/main/urls.py", line 23, in <module>
    from guest.views import SignUpView
  File "/projects/Python/Django/guestbook/main/guest/views.py", line 4, in <module>
    from .forms import StudentSignUpForm
  File "/projects/Python/Django/guestbook/main/guest/forms.py", line 23, in <module>
    class StudentSignUpForm(UserCreationForm):
  File "/projects/Python/Django/guestbook/main/guest/forms.py", line 27, in StudentSignUpForm
    required=True
TypeError: __init__() missing 1 required positional argument: 'queryset'

/projects/Python/Django/guestbook/main/guest/forms.py changed, reloading.
Performing system checks...

Exception in thread django-main-thread:
Traceback (most recent call last):
  File "/usr/lib/python3.6/threading.py", line 916, in _bootstrap_inner
    self.run()
  File "/usr/lib/python3.6/threading.py", line 864, in run
    self._target(*self._args, **self._kwargs)
  File "/projects/Python/Django/guestbook/venv/lib/python3.6/site-packages/django/utils/autoreload.py", line 54, in wrapper
    fn(*args, **kwargs)
  File "/projects/Python/Django/guestbook/venv/lib/python3.6/site-packages/django/core/management/commands/runserver.py", line 117, in inner_run
    self.check(display_num_errors=True)
  File "/projects/Python/Django/guestbook/venv/lib/python3.6/site-packages/django/core/management/base.py", line 390, in check
    include_deployment_checks=include_deployment_checks,
  File "/projects/Python/Django/guestbook/venv/lib/python3.6/site-packages/django/core/management/base.py", line 377, in _run_checks
    return checks.run_checks(**kwargs)
  File "/projects/Python/Django/guestbook/venv/lib/python3.6/site-packages/django/core/checks/registry.py", line 72, in run_checks
    new_errors = check(app_configs=app_configs)
  File "/projects/Python/Django/guestbook/venv/lib/python3.6/site-packages/django/core/checks/urls.py", line 13, in check_url_config
    return check_resolver(resolver)
  File "/projects/Python/Django/guestbook/venv/lib/python3.6/site-packages/django/core/checks/urls.py", line 23, in check_resolver
    return check_method()
  File "/projects/Python/Django/guestbook/venv/lib/python3.6/site-packages/django/urls/resolvers.py", line 398, in check
    for pattern in self.url_patterns:
  File "/projects/Python/Django/guestbook/venv/lib/python3.6/site-packages/django/utils/functional.py", line 80, in __get__
    res = instance.__dict__[self.name] = self.func(instance)
  File "/projects/Python/Django/guestbook/venv/lib/python3.6/site-packages/django/urls/resolvers.py", line 579, in url_patterns
    patterns = getattr(self.urlconf_module, "urlpatterns", self.urlconf_module)
  File "/projects/Python/Django/guestbook/venv/lib/python3.6/site-packages/django/utils/functional.py", line 80, in __get__
    res = instance.__dict__[self.name] = self.func(instance)
  File "/projects/Python/Django/guestbook/venv/lib/python3.6/site-packages/django/urls/resolvers.py", line 572, in urlconf_module
    return import_module(self.urlconf_name)
  File "/projects/Python/Django/guestbook/venv/lib/python3.6/importlib/__init__.py", line 126, in import_module
    return _bootstrap._gcd_import(name[level:], package, level)
  File "<frozen importlib._bootstrap>", line 994, in _gcd_import
  File "<frozen importlib._bootstrap>", line 971, in _find_and_load
  File "<frozen importlib._bootstrap>", line 955, in _find_and_load_unlocked
  File "<frozen importlib._bootstrap>", line 665, in _load_unlocked
  File "<frozen importlib._bootstrap_external>", line 678, in exec_module
  File "<frozen importlib._bootstrap>", line 219, in _call_with_frames_removed
  File "/projects/Python/Django/guestbook/main/main/urls.py", line 23, in <module>
    from guest.views import SignUpView
  File "/projects/Python/Django/guestbook/main/guest/views.py", line 4, in <module>
    from .forms import StudentSignUpForm
  File "/projects/Python/Django/guestbook/main/guest/forms.py", line 23, in <module>
    class StudentSignUpForm(UserCreationForm):
  File "/projects/Python/Django/guestbook/main/guest/forms.py", line 27, in StudentSignUpForm
    required=True
TypeError: __init__() missing 1 required positional argument: 'queryset'

/projects/Python/Django/guestbook/main/guest/forms.py changed, reloading.
Performing system checks...

Watching for file changes with StatReloader
Watching for file changes with StatReloader
Exception in thread django-main-thread:
Traceback (most recent call last):
  File "/usr/lib/python3.6/threading.py", line 916, in _bootstrap_inner
    self.run()
  File "/usr/lib/python3.6/threading.py", line 864, in run
    self._target(*self._args, **self._kwargs)
  File "/projects/Python/Django/guestbook/venv/lib/python3.6/site-packages/django/utils/autoreload.py", line 54, in wrapper
    fn(*args, **kwargs)
  File "/projects/Python/Django/guestbook/venv/lib/python3.6/site-packages/django/core/management/commands/runserver.py", line 117, in inner_run
    self.check(display_num_errors=True)
  File "/projects/Python/Django/guestbook/venv/lib/python3.6/site-packages/django/core/management/base.py", line 390, in check
    include_deployment_checks=include_deployment_checks,
  File "/projects/Python/Django/guestbook/venv/lib/python3.6/site-packages/django/core/management/base.py", line 377, in _run_checks
    return checks.run_checks(**kwargs)
  File "/projects/Python/Django/guestbook/venv/lib/python3.6/site-packages/django/core/checks/registry.py", line 72, in run_checks
    new_errors = check(app_configs=app_configs)
  File "/projects/Python/Django/guestbook/venv/lib/python3.6/site-packages/django/core/checks/urls.py", line 13, in check_url_config
    return check_resolver(resolver)
  File "/projects/Python/Django/guestbook/venv/lib/python3.6/site-packages/django/core/checks/urls.py", line 23, in check_resolver
    return check_method()
  File "/projects/Python/Django/guestbook/venv/lib/python3.6/site-packages/django/urls/resolvers.py", line 398, in check
    for pattern in self.url_patterns:
  File "/projects/Python/Django/guestbook/venv/lib/python3.6/site-packages/django/utils/functional.py", line 80, in __get__
    res = instance.__dict__[self.name] = self.func(instance)
  File "/projects/Python/Django/guestbook/venv/lib/python3.6/site-packages/django/urls/resolvers.py", line 579, in url_patterns
    patterns = getattr(self.urlconf_module, "urlpatterns", self.urlconf_module)
  File "/projects/Python/Django/guestbook/venv/lib/python3.6/site-packages/django/utils/functional.py", line 80, in __get__
    res = instance.__dict__[self.name] = self.func(instance)
  File "/projects/Python/Django/guestbook/venv/lib/python3.6/site-packages/django/urls/resolvers.py", line 572, in urlconf_module
    return import_module(self.urlconf_name)
  File "/projects/Python/Django/guestbook/venv/lib/python3.6/importlib/__init__.py", line 126, in import_module
    return _bootstrap._gcd_import(name[level:], package, level)
  File "<frozen importlib._bootstrap>", line 994, in _gcd_import
  File "<frozen importlib._bootstrap>", line 971, in _find_and_load
  File "<frozen importlib._bootstrap>", line 955, in _find_and_load_unlocked
  File "<frozen importlib._bootstrap>", line 665, in _load_unlocked
  File "<frozen importlib._bootstrap_external>", line 678, in exec_module
  File "<frozen importlib._bootstrap>", line 219, in _call_with_frames_removed
  File "/projects/Python/Django/guestbook/main/main/urls.py", line 23, in <module>
    from guest.views import SignUpView
  File "/projects/Python/Django/guestbook/main/guest/views.py", line 5, in <module>
    from .forms import StudentSignUpForm
  File "/projects/Python/Django/guestbook/main/guest/forms.py", line 23, in <module>
    class StudentSignUpForm(UserCreationForm):
  File "/projects/Python/Django/guestbook/main/guest/forms.py", line 27, in StudentSignUpForm
    required=True
TypeError: __init__() missing 1 required positional argument: 'queryset'

/projects/Python/Django/guestbook/main/guest/forms.py changed, reloading.
Performing system checks...

Exception in thread django-main-thread:
Traceback (most recent call last):
  File "/usr/lib/python3.6/threading.py", line 916, in _bootstrap_inner
    self.run()
  File "/usr/lib/python3.6/threading.py", line 864, in run
    self._target(*self._args, **self._kwargs)
  File "/projects/Python/Django/guestbook/venv/lib/python3.6/site-packages/django/utils/autoreload.py", line 54, in wrapper
    fn(*args, **kwargs)
  File "/projects/Python/Django/guestbook/venv/lib/python3.6/site-packages/django/core/management/commands/runserver.py", line 117, in inner_run
    self.check(display_num_errors=True)
  File "/projects/Python/Django/guestbook/venv/lib/python3.6/site-packages/django/core/management/base.py", line 390, in check
    include_deployment_checks=include_deployment_checks,
  File "/projects/Python/Django/guestbook/venv/lib/python3.6/site-packages/django/core/management/base.py", line 377, in _run_checks
    return checks.run_checks(**kwargs)
  File "/projects/Python/Django/guestbook/venv/lib/python3.6/site-packages/django/core/checks/registry.py", line 72, in run_checks
    new_errors = check(app_configs=app_configs)
  File "/projects/Python/Django/guestbook/venv/lib/python3.6/site-packages/django/core/checks/urls.py", line 13, in check_url_config
    return check_resolver(resolver)
  File "/projects/Python/Django/guestbook/venv/lib/python3.6/site-packages/django/core/checks/urls.py", line 23, in check_resolver
    return check_method()
  File "/projects/Python/Django/guestbook/venv/lib/python3.6/site-packages/django/urls/resolvers.py", line 398, in check
    for pattern in self.url_patterns:
  File "/projects/Python/Django/guestbook/venv/lib/python3.6/site-packages/django/utils/functional.py", line 80, in __get__
    res = instance.__dict__[self.name] = self.func(instance)
  File "/projects/Python/Django/guestbook/venv/lib/python3.6/site-packages/django/urls/resolvers.py", line 579, in url_patterns
    patterns = getattr(self.urlconf_module, "urlpatterns", self.urlconf_module)
  File "/projects/Python/Django/guestbook/venv/lib/python3.6/site-packages/django/utils/functional.py", line 80, in __get__
    res = instance.__dict__[self.name] = self.func(instance)
  File "/projects/Python/Django/guestbook/venv/lib/python3.6/site-packages/django/urls/resolvers.py", line 572, in urlconf_module
    return import_module(self.urlconf_name)
  File "/projects/Python/Django/guestbook/venv/lib/python3.6/importlib/__init__.py", line 126, in import_module
    return _bootstrap._gcd_import(name[level:], package, level)
  File "<frozen importlib._bootstrap>", line 994, in _gcd_import
  File "<frozen importlib._bootstrap>", line 971, in _find_and_load
  File "<frozen importlib._bootstrap>", line 955, in _find_and_load_unlocked
  File "<frozen importlib._bootstrap>", line 665, in _load_unlocked
  File "<frozen importlib._bootstrap_external>", line 678, in exec_module
  File "<frozen importlib._bootstrap>", line 219, in _call_with_frames_removed
  File "/projects/Python/Django/guestbook/main/main/urls.py", line 23, in <module>
    from guest.views import SignUpView
  File "/projects/Python/Django/guestbook/main/guest/views.py", line 5, in <module>
    from .forms import StudentSignUpForm
  File "/projects/Python/Django/guestbook/main/guest/forms.py", line 23, in <module>
    class StudentSignUpForm(UserCreationForm):
  File "/projects/Python/Django/guestbook/main/guest/forms.py", line 27, in StudentSignUpForm
    required=True
TypeError: __init__() missing 1 required positional argument: 'queryset'

/projects/Python/Django/guestbook/main/guest/forms.py changed, reloading.
Performing system checks...

Watching for file changes with StatReloader
Watching for file changes with StatReloader
Exception in thread django-main-thread:
Traceback (most recent call last):
  File "/usr/lib/python3.6/threading.py", line 916, in _bootstrap_inner
    self.run()
  File "/usr/lib/python3.6/threading.py", line 864, in run
    self._target(*self._args, **self._kwargs)
  File "/projects/Python/Django/guestbook/venv/lib/python3.6/site-packages/django/utils/autoreload.py", line 54, in wrapper
    fn(*args, **kwargs)
  File "/projects/Python/Django/guestbook/venv/lib/python3.6/site-packages/django/core/management/commands/runserver.py", line 117, in inner_run
    self.check(display_num_errors=True)
  File "/projects/Python/Django/guestbook/venv/lib/python3.6/site-packages/django/core/management/base.py", line 390, in check
    include_deployment_checks=include_deployment_checks,
  File "/projects/Python/Django/guestbook/venv/lib/python3.6/site-packages/django/core/management/base.py", line 377, in _run_checks
    return checks.run_checks(**kwargs)
  File "/projects/Python/Django/guestbook/venv/lib/python3.6/site-packages/django/core/checks/registry.py", line 72, in run_checks
    new_errors = check(app_configs=app_configs)
  File "/projects/Python/Django/guestbook/venv/lib/python3.6/site-packages/django/core/checks/urls.py", line 13, in check_url_config
    return check_resolver(resolver)
  File "/projects/Python/Django/guestbook/venv/lib/python3.6/site-packages/django/core/checks/urls.py", line 23, in check_resolver
    return check_method()
  File "/projects/Python/Django/guestbook/venv/lib/python3.6/site-packages/django/urls/resolvers.py", line 398, in check
    for pattern in self.url_patterns:
  File "/projects/Python/Django/guestbook/venv/lib/python3.6/site-packages/django/utils/functional.py", line 80, in __get__
    res = instance.__dict__[self.name] = self.func(instance)
  File "/projects/Python/Django/guestbook/venv/lib/python3.6/site-packages/django/urls/resolvers.py", line 579, in url_patterns
    patterns = getattr(self.urlconf_module, "urlpatterns", self.urlconf_module)
  File "/projects/Python/Django/guestbook/venv/lib/python3.6/site-packages/django/utils/functional.py", line 80, in __get__
    res = instance.__dict__[self.name] = self.func(instance)
  File "/projects/Python/Django/guestbook/venv/lib/python3.6/site-packages/django/urls/resolvers.py", line 572, in urlconf_module
    return import_module(self.urlconf_name)
  File "/projects/Python/Django/guestbook/venv/lib/python3.6/importlib/__init__.py", line 126, in import_module
    return _bootstrap._gcd_import(name[level:], package, level)
  File "<frozen importlib._bootstrap>", line 994, in _gcd_import
  File "<frozen importlib._bootstrap>", line 971, in _find_and_load
  File "<frozen importlib._bootstrap>", line 955, in _find_and_load_unlocked
  File "<frozen importlib._bootstrap>", line 665, in _load_unlocked
  File "<frozen importlib._bootstrap_external>", line 678, in exec_module
  File "<frozen importlib._bootstrap>", line 219, in _call_with_frames_removed
  File "/projects/Python/Django/guestbook/main/main/urls.py", line 23, in <module>
    from guest.views import SignUpView
  File "/projects/Python/Django/guestbook/main/guest/views.py", line 5, in <module>
    from .forms import StudentSignUpForm
  File "/projects/Python/Django/guestbook/main/guest/forms.py", line 23, in <module>
    class StudentSignUpForm(UserCreationForm):
  File "/projects/Python/Django/guestbook/main/guest/forms.py", line 27, in StudentSignUpForm
    required=True
TypeError: __init__() missing 1 required positional argument: 'queryset'

/projects/Python/Django/guestbook/main/guest/forms.py changed, reloading.
Performing system checks...

Watching for file changes with StatReloader
Exception in thread django-main-thread:
Traceback (most recent call last):
  File "/usr/lib/python3.6/threading.py", line 916, in _bootstrap_inner
    self.run()
  File "/usr/lib/python3.6/threading.py", line 864, in run
    self._target(*self._args, **self._kwargs)
  File "/projects/Python/Django/guestbook/venv/lib/python3.6/site-packages/django/utils/autoreload.py", line 54, in wrapper
    fn(*args, **kwargs)
  File "/projects/Python/Django/guestbook/venv/lib/python3.6/site-packages/django/core/management/commands/runserver.py", line 117, in inner_run
    self.check(display_num_errors=True)
  File "/projects/Python/Django/guestbook/venv/lib/python3.6/site-packages/django/core/management/base.py", line 390, in check
    include_deployment_checks=include_deployment_checks,
  File "/projects/Python/Django/guestbook/venv/lib/python3.6/site-packages/django/core/management/base.py", line 377, in _run_checks
    return checks.run_checks(**kwargs)
  File "/projects/Python/Django/guestbook/venv/lib/python3.6/site-packages/django/core/checks/registry.py", line 72, in run_checks
    new_errors = check(app_configs=app_configs)
  File "/projects/Python/Django/guestbook/venv/lib/python3.6/site-packages/django/core/checks/urls.py", line 13, in check_url_config
    return check_resolver(resolver)
  File "/projects/Python/Django/guestbook/venv/lib/python3.6/site-packages/django/core/checks/urls.py", line 23, in check_resolver
    return check_method()
  File "/projects/Python/Django/guestbook/venv/lib/python3.6/site-packages/django/urls/resolvers.py", line 398, in check
    for pattern in self.url_patterns:
  File "/projects/Python/Django/guestbook/venv/lib/python3.6/site-packages/django/utils/functional.py", line 80, in __get__
    res = instance.__dict__[self.name] = self.func(instance)
  File "/projects/Python/Django/guestbook/venv/lib/python3.6/site-packages/django/urls/resolvers.py", line 579, in url_patterns
    patterns = getattr(self.urlconf_module, "urlpatterns", self.urlconf_module)
  File "/projects/Python/Django/guestbook/venv/lib/python3.6/site-packages/django/utils/functional.py", line 80, in __get__
    res = instance.__dict__[self.name] = self.func(instance)
  File "/projects/Python/Django/guestbook/venv/lib/python3.6/site-packages/django/urls/resolvers.py", line 572, in urlconf_module
    return import_module(self.urlconf_name)
  File "/projects/Python/Django/guestbook/venv/lib/python3.6/importlib/__init__.py", line 126, in import_module
    return _bootstrap._gcd_import(name[level:], package, level)
  File "<frozen importlib._bootstrap>", line 994, in _gcd_import
  File "<frozen importlib._bootstrap>", line 971, in _find_and_load
  File "<frozen importlib._bootstrap>", line 955, in _find_and_load_unlocked
  File "<frozen importlib._bootstrap>", line 665, in _load_unlocked
  File "<frozen importlib._bootstrap_external>", line 678, in exec_module
  File "<frozen importlib._bootstrap>", line 219, in _call_with_frames_removed
  File "/projects/Python/Django/guestbook/main/main/urls.py", line 23, in <module>
    from guest.views import SignUpView
  File "/projects/Python/Django/guestbook/main/guest/views.py", line 5, in <module>
    from .forms import StudentSignUpForm
  File "/projects/Python/Django/guestbook/main/guest/forms.py", line 23, in <module>
    class StudentSignUpForm(UserCreationForm):
  File "/projects/Python/Django/guestbook/main/guest/forms.py", line 27, in StudentSignUpForm
    required=True
TypeError: __init__() missing 1 required positional argument: 'queryset'

/projects/Python/Django/guestbook/main/guest/forms.py changed, reloading.
Performing system checks...

Watching for file changes with StatReloader
Exception in thread django-main-thread:
Traceback (most recent call last):
  File "/usr/lib/python3.6/threading.py", line 916, in _bootstrap_inner
    self.run()
  File "/usr/lib/python3.6/threading.py", line 864, in run
    self._target(*self._args, **self._kwargs)
  File "/projects/Python/Django/guestbook/venv/lib/python3.6/site-packages/django/utils/autoreload.py", line 54, in wrapper
    fn(*args, **kwargs)
  File "/projects/Python/Django/guestbook/venv/lib/python3.6/site-packages/django/core/management/commands/runserver.py", line 117, in inner_run
    self.check(display_num_errors=True)
  File "/projects/Python/Django/guestbook/venv/lib/python3.6/site-packages/django/core/management/base.py", line 390, in check
    include_deployment_checks=include_deployment_checks,
  File "/projects/Python/Django/guestbook/venv/lib/python3.6/site-packages/django/core/management/base.py", line 377, in _run_checks
    return checks.run_checks(**kwargs)
  File "/projects/Python/Django/guestbook/venv/lib/python3.6/site-packages/django/core/checks/registry.py", line 72, in run_checks
    new_errors = check(app_configs=app_configs)
  File "/projects/Python/Django/guestbook/venv/lib/python3.6/site-packages/django/core/checks/urls.py", line 13, in check_url_config
    return check_resolver(resolver)
  File "/projects/Python/Django/guestbook/venv/lib/python3.6/site-packages/django/core/checks/urls.py", line 23, in check_resolver
    return check_method()
  File "/projects/Python/Django/guestbook/venv/lib/python3.6/site-packages/django/urls/resolvers.py", line 398, in check
    for pattern in self.url_patterns:
  File "/projects/Python/Django/guestbook/venv/lib/python3.6/site-packages/django/utils/functional.py", line 80, in __get__
    res = instance.__dict__[self.name] = self.func(instance)
  File "/projects/Python/Django/guestbook/venv/lib/python3.6/site-packages/django/urls/resolvers.py", line 579, in url_patterns
    patterns = getattr(self.urlconf_module, "urlpatterns", self.urlconf_module)
  File "/projects/Python/Django/guestbook/venv/lib/python3.6/site-packages/django/utils/functional.py", line 80, in __get__
    res = instance.__dict__[self.name] = self.func(instance)
  File "/projects/Python/Django/guestbook/venv/lib/python3.6/site-packages/django/urls/resolvers.py", line 572, in urlconf_module
    return import_module(self.urlconf_name)
  File "/projects/Python/Django/guestbook/venv/lib/python3.6/importlib/__init__.py", line 126, in import_module
    return _bootstrap._gcd_import(name[level:], package, level)
  File "<frozen importlib._bootstrap>", line 994, in _gcd_import
  File "<frozen importlib._bootstrap>", line 971, in _find_and_load
  File "<frozen importlib._bootstrap>", line 955, in _find_and_load_unlocked
  File "<frozen importlib._bootstrap>", line 665, in _load_unlocked
  File "<frozen importlib._bootstrap_external>", line 678, in exec_module
  File "<frozen importlib._bootstrap>", line 219, in _call_with_frames_removed
  File "/projects/Python/Django/guestbook/main/main/urls.py", line 23, in <module>
    from guest.views import SignUpView
  File "/projects/Python/Django/guestbook/main/guest/views.py", line 5, in <module>
    from .forms import StudentSignUpForm
  File "/projects/Python/Django/guestbook/main/guest/forms.py", line 23, in <module>
    class StudentSignUpForm(UserCreationForm):
  File "/projects/Python/Django/guestbook/main/guest/forms.py", line 27, in StudentSignUpForm
    required=True
TypeError: __init__() missing 1 required positional argument: 'queryset'

/projects/Python/Django/guestbook/main/guest/forms.py changed, reloading.
Performing system checks...

Watching for file changes with StatReloader
Exception in thread django-main-thread:
Traceback (most recent call last):
  File "/usr/lib/python3.6/threading.py", line 916, in _bootstrap_inner
    self.run()
  File "/usr/lib/python3.6/threading.py", line 864, in run
    self._target(*self._args, **self._kwargs)
  File "/projects/Python/Django/guestbook/venv/lib/python3.6/site-packages/django/utils/autoreload.py", line 54, in wrapper
    fn(*args, **kwargs)
  File "/projects/Python/Django/guestbook/venv/lib/python3.6/site-packages/django/core/management/commands/runserver.py", line 117, in inner_run
    self.check(display_num_errors=True)
  File "/projects/Python/Django/guestbook/venv/lib/python3.6/site-packages/django/core/management/base.py", line 390, in check
    include_deployment_checks=include_deployment_checks,
  File "/projects/Python/Django/guestbook/venv/lib/python3.6/site-packages/django/core/management/base.py", line 377, in _run_checks
    return checks.run_checks(**kwargs)
  File "/projects/Python/Django/guestbook/venv/lib/python3.6/site-packages/django/core/checks/registry.py", line 72, in run_checks
    new_errors = check(app_configs=app_configs)
  File "/projects/Python/Django/guestbook/venv/lib/python3.6/site-packages/django/core/checks/urls.py", line 13, in check_url_config
    return check_resolver(resolver)
  File "/projects/Python/Django/guestbook/venv/lib/python3.6/site-packages/django/core/checks/urls.py", line 23, in check_resolver
    return check_method()
  File "/projects/Python/Django/guestbook/venv/lib/python3.6/site-packages/django/urls/resolvers.py", line 398, in check
    for pattern in self.url_patterns:
  File "/projects/Python/Django/guestbook/venv/lib/python3.6/site-packages/django/utils/functional.py", line 80, in __get__
    res = instance.__dict__[self.name] = self.func(instance)
  File "/projects/Python/Django/guestbook/venv/lib/python3.6/site-packages/django/urls/resolvers.py", line 579, in url_patterns
    patterns = getattr(self.urlconf_module, "urlpatterns", self.urlconf_module)
  File "/projects/Python/Django/guestbook/venv/lib/python3.6/site-packages/django/utils/functional.py", line 80, in __get__
    res = instance.__dict__[self.name] = self.func(instance)
  File "/projects/Python/Django/guestbook/venv/lib/python3.6/site-packages/django/urls/resolvers.py", line 572, in urlconf_module
    return import_module(self.urlconf_name)
  File "/projects/Python/Django/guestbook/venv/lib/python3.6/importlib/__init__.py", line 126, in import_module
    return _bootstrap._gcd_import(name[level:], package, level)
  File "<frozen importlib._bootstrap>", line 994, in _gcd_import
  File "<frozen importlib._bootstrap>", line 971, in _find_and_load
  File "<frozen importlib._bootstrap>", line 955, in _find_and_load_unlocked
  File "<frozen importlib._bootstrap>", line 665, in _load_unlocked
  File "<frozen importlib._bootstrap_external>", line 678, in exec_module
  File "<frozen importlib._bootstrap>", line 219, in _call_with_frames_removed
  File "/projects/Python/Django/guestbook/main/main/urls.py", line 23, in <module>
    from guest.views import SignUpView
  File "/projects/Python/Django/guestbook/main/guest/views.py", line 5, in <module>
    from .forms import StudentSignUpForm
  File "/projects/Python/Django/guestbook/main/guest/forms.py", line 23, in <module>
    class StudentSignUpForm(UserCreationForm):
  File "/projects/Python/Django/guestbook/main/guest/forms.py", line 27, in StudentSignUpForm
    required=True
TypeError: __init__() missing 1 required positional argument: 'queryset'

/projects/Python/Django/guestbook/main/guest/forms.py changed, reloading.
Performing system checks...

Watching for file changes with StatReloader
Exception in thread django-main-thread:
Traceback (most recent call last):
  File "/usr/lib/python3.6/threading.py", line 916, in _bootstrap_inner
    self.run()
  File "/usr/lib/python3.6/threading.py", line 864, in run
    self._target(*self._args, **self._kwargs)
  File "/projects/Python/Django/guestbook/venv/lib/python3.6/site-packages/django/utils/autoreload.py", line 54, in wrapper
    fn(*args, **kwargs)
  File "/projects/Python/Django/guestbook/venv/lib/python3.6/site-packages/django/core/management/commands/runserver.py", line 117, in inner_run
    self.check(display_num_errors=True)
  File "/projects/Python/Django/guestbook/venv/lib/python3.6/site-packages/django/core/management/base.py", line 390, in check
    include_deployment_checks=include_deployment_checks,
  File "/projects/Python/Django/guestbook/venv/lib/python3.6/site-packages/django/core/management/base.py", line 377, in _run_checks
    return checks.run_checks(**kwargs)
  File "/projects/Python/Django/guestbook/venv/lib/python3.6/site-packages/django/core/checks/registry.py", line 72, in run_checks
    new_errors = check(app_configs=app_configs)
  File "/projects/Python/Django/guestbook/venv/lib/python3.6/site-packages/django/core/checks/urls.py", line 13, in check_url_config
    return check_resolver(resolver)
  File "/projects/Python/Django/guestbook/venv/lib/python3.6/site-packages/django/core/checks/urls.py", line 23, in check_resolver
    return check_method()
  File "/projects/Python/Django/guestbook/venv/lib/python3.6/site-packages/django/urls/resolvers.py", line 398, in check
    for pattern in self.url_patterns:
  File "/projects/Python/Django/guestbook/venv/lib/python3.6/site-packages/django/utils/functional.py", line 80, in __get__
    res = instance.__dict__[self.name] = self.func(instance)
  File "/projects/Python/Django/guestbook/venv/lib/python3.6/site-packages/django/urls/resolvers.py", line 579, in url_patterns
    patterns = getattr(self.urlconf_module, "urlpatterns", self.urlconf_module)
  File "/projects/Python/Django/guestbook/venv/lib/python3.6/site-packages/django/utils/functional.py", line 80, in __get__
    res = instance.__dict__[self.name] = self.func(instance)
  File "/projects/Python/Django/guestbook/venv/lib/python3.6/site-packages/django/urls/resolvers.py", line 572, in urlconf_module
    return import_module(self.urlconf_name)
  File "/projects/Python/Django/guestbook/venv/lib/python3.6/importlib/__init__.py", line 126, in import_module
    return _bootstrap._gcd_import(name[level:], package, level)
  File "<frozen importlib._bootstrap>", line 994, in _gcd_import
  File "<frozen importlib._bootstrap>", line 971, in _find_and_load
  File "<frozen importlib._bootstrap>", line 955, in _find_and_load_unlocked
  File "<frozen importlib._bootstrap>", line 665, in _load_unlocked
  File "<frozen importlib._bootstrap_external>", line 678, in exec_module
  File "<frozen importlib._bootstrap>", line 219, in _call_with_frames_removed
  File "/projects/Python/Django/guestbook/main/main/urls.py", line 23, in <module>
    from guest.views import SignUpView
  File "/projects/Python/Django/guestbook/main/guest/views.py", line 5, in <module>
    from .forms import StudentSignUpForm
  File "/projects/Python/Django/guestbook/main/guest/forms.py", line 23, in <module>
    class StudentSignUpForm(UserCreationForm):
  File "/projects/Python/Django/guestbook/main/guest/forms.py", line 27, in StudentSignUpForm
    required=True
TypeError: __init__() missing 1 required positional argument: 'queryset'

/projects/Python/Django/guestbook/main/guest/forms.py changed, reloading.
Performing system checks...

Exception in thread django-main-thread:
Traceback (most recent call last):
  File "/usr/lib/python3.6/threading.py", line 916, in _bootstrap_inner
    self.run()
  File "/usr/lib/python3.6/threading.py", line 864, in run
    self._target(*self._args, **self._kwargs)
  File "/projects/Python/Django/guestbook/venv/lib/python3.6/site-packages/django/utils/autoreload.py", line 54, in wrapper
    fn(*args, **kwargs)
  File "/projects/Python/Django/guestbook/venv/lib/python3.6/site-packages/django/core/management/commands/runserver.py", line 117, in inner_run
    self.check(display_num_errors=True)
  File "/projects/Python/Django/guestbook/venv/lib/python3.6/site-packages/django/core/management/base.py", line 390, in check
    include_deployment_checks=include_deployment_checks,
  File "/projects/Python/Django/guestbook/venv/lib/python3.6/site-packages/django/core/management/base.py", line 377, in _run_checks
    return checks.run_checks(**kwargs)
  File "/projects/Python/Django/guestbook/venv/lib/python3.6/site-packages/django/core/checks/registry.py", line 72, in run_checks
    new_errors = check(app_configs=app_configs)
  File "/projects/Python/Django/guestbook/venv/lib/python3.6/site-packages/django/core/checks/urls.py", line 13, in check_url_config
    return check_resolver(resolver)
  File "/projects/Python/Django/guestbook/venv/lib/python3.6/site-packages/django/core/checks/urls.py", line 23, in check_resolver
    return check_method()
  File "/projects/Python/Django/guestbook/venv/lib/python3.6/site-packages/django/urls/resolvers.py", line 398, in check
    for pattern in self.url_patterns:
  File "/projects/Python/Django/guestbook/venv/lib/python3.6/site-packages/django/utils/functional.py", line 80, in __get__
    res = instance.__dict__[self.name] = self.func(instance)
  File "/projects/Python/Django/guestbook/venv/lib/python3.6/site-packages/django/urls/resolvers.py", line 579, in url_patterns
    patterns = getattr(self.urlconf_module, "urlpatterns", self.urlconf_module)
  File "/projects/Python/Django/guestbook/venv/lib/python3.6/site-packages/django/utils/functional.py", line 80, in __get__
    res = instance.__dict__[self.name] = self.func(instance)
  File "/projects/Python/Django/guestbook/venv/lib/python3.6/site-packages/django/urls/resolvers.py", line 572, in urlconf_module
    return import_module(self.urlconf_name)
  File "/projects/Python/Django/guestbook/venv/lib/python3.6/importlib/__init__.py", line 126, in import_module
    return _bootstrap._gcd_import(name[level:], package, level)
  File "<frozen importlib._bootstrap>", line 994, in _gcd_import
  File "<frozen importlib._bootstrap>", line 971, in _find_and_load
  File "<frozen importlib._bootstrap>", line 955, in _find_and_load_unlocked
  File "<frozen importlib._bootstrap>", line 665, in _load_unlocked
  File "<frozen importlib._bootstrap_external>", line 678, in exec_module
  File "<frozen importlib._bootstrap>", line 219, in _call_with_frames_removed
  File "/projects/Python/Django/guestbook/main/main/urls.py", line 23, in <module>
    from guest.views import SignUpView
  File "/projects/Python/Django/guestbook/main/guest/views.py", line 5, in <module>
    from .forms import StudentSignUpForm
  File "/projects/Python/Django/guestbook/main/guest/forms.py", line 23, in <module>
    class StudentSignUpForm(UserCreationForm):
  File "/projects/Python/Django/guestbook/main/guest/forms.py", line 27, in StudentSignUpForm
    required=True
TypeError: __init__() missing 1 required positional argument: 'queryset'

/projects/Python/Django/guestbook/main/guest/forms.py changed, reloading.
Performing system checks...

Watching for file changes with StatReloader
Watching for file changes with StatReloader
Exception in thread django-main-thread:
Traceback (most recent call last):
  File "/usr/lib/python3.6/threading.py", line 916, in _bootstrap_inner
    self.run()
  File "/usr/lib/python3.6/threading.py", line 864, in run
    self._target(*self._args, **self._kwargs)
  File "/projects/Python/Django/guestbook/venv/lib/python3.6/site-packages/django/utils/autoreload.py", line 54, in wrapper
    fn(*args, **kwargs)
  File "/projects/Python/Django/guestbook/venv/lib/python3.6/site-packages/django/core/management/commands/runserver.py", line 117, in inner_run
    self.check(display_num_errors=True)
  File "/projects/Python/Django/guestbook/venv/lib/python3.6/site-packages/django/core/management/base.py", line 390, in check
    include_deployment_checks=include_deployment_checks,
  File "/projects/Python/Django/guestbook/venv/lib/python3.6/site-packages/django/core/management/base.py", line 377, in _run_checks
    return checks.run_checks(**kwargs)
  File "/projects/Python/Django/guestbook/venv/lib/python3.6/site-packages/django/core/checks/registry.py", line 72, in run_checks
    new_errors = check(app_configs=app_configs)
  File "/projects/Python/Django/guestbook/venv/lib/python3.6/site-packages/django/core/checks/urls.py", line 13, in check_url_config
    return check_resolver(resolver)
  File "/projects/Python/Django/guestbook/venv/lib/python3.6/site-packages/django/core/checks/urls.py", line 23, in check_resolver
    return check_method()
  File "/projects/Python/Django/guestbook/venv/lib/python3.6/site-packages/django/urls/resolvers.py", line 398, in check
    for pattern in self.url_patterns:
  File "/projects/Python/Django/guestbook/venv/lib/python3.6/site-packages/django/utils/functional.py", line 80, in __get__
    res = instance.__dict__[self.name] = self.func(instance)
  File "/projects/Python/Django/guestbook/venv/lib/python3.6/site-packages/django/urls/resolvers.py", line 579, in url_patterns
    patterns = getattr(self.urlconf_module, "urlpatterns", self.urlconf_module)
  File "/projects/Python/Django/guestbook/venv/lib/python3.6/site-packages/django/utils/functional.py", line 80, in __get__
    res = instance.__dict__[self.name] = self.func(instance)
  File "/projects/Python/Django/guestbook/venv/lib/python3.6/site-packages/django/urls/resolvers.py", line 572, in urlconf_module
    return import_module(self.urlconf_name)
  File "/projects/Python/Django/guestbook/venv/lib/python3.6/importlib/__init__.py", line 126, in import_module
    return _bootstrap._gcd_import(name[level:], package, level)
  File "<frozen importlib._bootstrap>", line 994, in _gcd_import
  File "<frozen importlib._bootstrap>", line 971, in _find_and_load
  File "<frozen importlib._bootstrap>", line 955, in _find_and_load_unlocked
  File "<frozen importlib._bootstrap>", line 665, in _load_unlocked
  File "<frozen importlib._bootstrap_external>", line 678, in exec_module
  File "<frozen importlib._bootstrap>", line 219, in _call_with_frames_removed
  File "/projects/Python/Django/guestbook/main/main/urls.py", line 23, in <module>
    from guest.views import SignUpView
  File "/projects/Python/Django/guestbook/main/guest/views.py", line 5, in <module>
    from .forms import StudentSignUpForm
  File "/projects/Python/Django/guestbook/main/guest/forms.py", line 23, in <module>
    class StudentSignUpForm(UserCreationForm):
  File "/projects/Python/Django/guestbook/main/guest/forms.py", line 27, in StudentSignUpForm
    required=True
TypeError: __init__() missing 1 required positional argument: 'queryset'

/projects/Python/Django/guestbook/main/guest/forms.py changed, reloading.
Performing system checks...

Exception in thread django-main-thread:
Traceback (most recent call last):
  File "/usr/lib/python3.6/threading.py", line 916, in _bootstrap_inner
    self.run()
  File "/usr/lib/python3.6/threading.py", line 864, in run
    self._target(*self._args, **self._kwargs)
  File "/projects/Python/Django/guestbook/venv/lib/python3.6/site-packages/django/utils/autoreload.py", line 54, in wrapper
    fn(*args, **kwargs)
  File "/projects/Python/Django/guestbook/venv/lib/python3.6/site-packages/django/core/management/commands/runserver.py", line 117, in inner_run
    self.check(display_num_errors=True)
  File "/projects/Python/Django/guestbook/venv/lib/python3.6/site-packages/django/core/management/base.py", line 390, in check
    include_deployment_checks=include_deployment_checks,
  File "/projects/Python/Django/guestbook/venv/lib/python3.6/site-packages/django/core/management/base.py", line 377, in _run_checks
    return checks.run_checks(**kwargs)
  File "/projects/Python/Django/guestbook/venv/lib/python3.6/site-packages/django/core/checks/registry.py", line 72, in run_checks
    new_errors = check(app_configs=app_configs)
  File "/projects/Python/Django/guestbook/venv/lib/python3.6/site-packages/django/core/checks/urls.py", line 13, in check_url_config
    return check_resolver(resolver)
  File "/projects/Python/Django/guestbook/venv/lib/python3.6/site-packages/django/core/checks/urls.py", line 23, in check_resolver
    return check_method()
  File "/projects/Python/Django/guestbook/venv/lib/python3.6/site-packages/django/urls/resolvers.py", line 398, in check
    for pattern in self.url_patterns:
  File "/projects/Python/Django/guestbook/venv/lib/python3.6/site-packages/django/utils/functional.py", line 80, in __get__
    res = instance.__dict__[self.name] = self.func(instance)
  File "/projects/Python/Django/guestbook/venv/lib/python3.6/site-packages/django/urls/resolvers.py", line 579, in url_patterns
    patterns = getattr(self.urlconf_module, "urlpatterns", self.urlconf_module)
  File "/projects/Python/Django/guestbook/venv/lib/python3.6/site-packages/django/utils/functional.py", line 80, in __get__
    res = instance.__dict__[self.name] = self.func(instance)
  File "/projects/Python/Django/guestbook/venv/lib/python3.6/site-packages/django/urls/resolvers.py", line 572, in urlconf_module
    return import_module(self.urlconf_name)
  File "/projects/Python/Django/guestbook/venv/lib/python3.6/importlib/__init__.py", line 126, in import_module
    return _bootstrap._gcd_import(name[level:], package, level)
  File "<frozen importlib._bootstrap>", line 994, in _gcd_import
  File "<frozen importlib._bootstrap>", line 971, in _find_and_load
  File "<frozen importlib._bootstrap>", line 955, in _find_and_load_unlocked
  File "<frozen importlib._bootstrap>", line 665, in _load_unlocked
  File "<frozen importlib._bootstrap_external>", line 678, in exec_module
  File "<frozen importlib._bootstrap>", line 219, in _call_with_frames_removed
  File "/projects/Python/Django/guestbook/main/main/urls.py", line 23, in <module>
    from guest.views import SignUpView
  File "/projects/Python/Django/guestbook/main/guest/views.py", line 5, in <module>
    from .forms import StudentSignUpForm
  File "/projects/Python/Django/guestbook/main/guest/forms.py", line 23, in <module>
    class StudentSignUpForm(UserCreationForm):
  File "/projects/Python/Django/guestbook/main/guest/forms.py", line 27, in StudentSignUpForm
    required=True
TypeError: __init__() missing 1 required positional argument: 'queryset'

/projects/Python/Django/guestbook/main/guest/forms.py changed, reloading.
Performing system checks...

Watching for file changes with StatReloader
Watching for file changes with StatReloader
Watching for file changes with StatReloader
Exception in thread django-main-thread:
Traceback (most recent call last):
  File "/usr/lib/python3.6/threading.py", line 916, in _bootstrap_inner
    self.run()
  File "/usr/lib/python3.6/threading.py", line 864, in run
    self._target(*self._args, **self._kwargs)
  File "/projects/Python/Django/guestbook/venv/lib/python3.6/site-packages/django/utils/autoreload.py", line 54, in wrapper
    fn(*args, **kwargs)
  File "/projects/Python/Django/guestbook/venv/lib/python3.6/site-packages/django/core/management/commands/runserver.py", line 117, in inner_run
    self.check(display_num_errors=True)
  File "/projects/Python/Django/guestbook/venv/lib/python3.6/site-packages/django/core/management/base.py", line 390, in check
    include_deployment_checks=include_deployment_checks,
  File "/projects/Python/Django/guestbook/venv/lib/python3.6/site-packages/django/core/management/base.py", line 377, in _run_checks
    return checks.run_checks(**kwargs)
  File "/projects/Python/Django/guestbook/venv/lib/python3.6/site-packages/django/core/checks/registry.py", line 72, in run_checks
    new_errors = check(app_configs=app_configs)
  File "/projects/Python/Django/guestbook/venv/lib/python3.6/site-packages/django/core/checks/urls.py", line 13, in check_url_config
    return check_resolver(resolver)
  File "/projects/Python/Django/guestbook/venv/lib/python3.6/site-packages/django/core/checks/urls.py", line 23, in check_resolver
    return check_method()
  File "/projects/Python/Django/guestbook/venv/lib/python3.6/site-packages/django/urls/resolvers.py", line 398, in check
    for pattern in self.url_patterns:
  File "/projects/Python/Django/guestbook/venv/lib/python3.6/site-packages/django/utils/functional.py", line 80, in __get__
    res = instance.__dict__[self.name] = self.func(instance)
  File "/projects/Python/Django/guestbook/venv/lib/python3.6/site-packages/django/urls/resolvers.py", line 579, in url_patterns
    patterns = getattr(self.urlconf_module, "urlpatterns", self.urlconf_module)
  File "/projects/Python/Django/guestbook/venv/lib/python3.6/site-packages/django/utils/functional.py", line 80, in __get__
    res = instance.__dict__[self.name] = self.func(instance)
  File "/projects/Python/Django/guestbook/venv/lib/python3.6/site-packages/django/urls/resolvers.py", line 572, in urlconf_module
    return import_module(self.urlconf_name)
  File "/projects/Python/Django/guestbook/venv/lib/python3.6/importlib/__init__.py", line 126, in import_module
    return _bootstrap._gcd_import(name[level:], package, level)
  File "<frozen importlib._bootstrap>", line 994, in _gcd_import
  File "<frozen importlib._bootstrap>", line 971, in _find_and_load
  File "<frozen importlib._bootstrap>", line 955, in _find_and_load_unlocked
  File "<frozen importlib._bootstrap>", line 665, in _load_unlocked
  File "<frozen importlib._bootstrap_external>", line 678, in exec_module
  File "<frozen importlib._bootstrap>", line 219, in _call_with_frames_removed
  File "/projects/Python/Django/guestbook/main/main/urls.py", line 23, in <module>
    from guest.views import SignUpView
  File "/projects/Python/Django/guestbook/main/guest/views.py", line 5, in <module>
    from .forms import StudentSignUpForm
  File "/projects/Python/Django/guestbook/main/guest/forms.py", line 23, in <module>
    class StudentSignUpForm(UserCreationForm):
  File "/projects/Python/Django/guestbook/main/guest/forms.py", line 27, in StudentSignUpForm
    required=True
TypeError: __init__() missing 1 required positional argument: 'queryset'

/projects/Python/Django/guestbook/main/guest/forms.py changed, reloading.
Performing system checks...

Exception in thread django-main-thread:
Traceback (most recent call last):
  File "/usr/lib/python3.6/threading.py", line 916, in _bootstrap_inner
    self.run()
  File "/usr/lib/python3.6/threading.py", line 864, in run
    self._target(*self._args, **self._kwargs)
  File "/projects/Python/Django/guestbook/venv/lib/python3.6/site-packages/django/utils/autoreload.py", line 54, in wrapper
    fn(*args, **kwargs)
  File "/projects/Python/Django/guestbook/venv/lib/python3.6/site-packages/django/core/management/commands/runserver.py", line 117, in inner_run
    self.check(display_num_errors=True)
  File "/projects/Python/Django/guestbook/venv/lib/python3.6/site-packages/django/core/management/base.py", line 390, in check
    include_deployment_checks=include_deployment_checks,
  File "/projects/Python/Django/guestbook/venv/lib/python3.6/site-packages/django/core/management/base.py", line 377, in _run_checks
    return checks.run_checks(**kwargs)
  File "/projects/Python/Django/guestbook/venv/lib/python3.6/site-packages/django/core/checks/registry.py", line 72, in run_checks
    new_errors = check(app_configs=app_configs)
  File "/projects/Python/Django/guestbook/venv/lib/python3.6/site-packages/django/core/checks/urls.py", line 13, in check_url_config
    return check_resolver(resolver)
  File "/projects/Python/Django/guestbook/venv/lib/python3.6/site-packages/django/core/checks/urls.py", line 23, in check_resolver
    return check_method()
  File "/projects/Python/Django/guestbook/venv/lib/python3.6/site-packages/django/urls/resolvers.py", line 398, in check
    for pattern in self.url_patterns:
  File "/projects/Python/Django/guestbook/venv/lib/python3.6/site-packages/django/utils/functional.py", line 80, in __get__
    res = instance.__dict__[self.name] = self.func(instance)
  File "/projects/Python/Django/guestbook/venv/lib/python3.6/site-packages/django/urls/resolvers.py", line 579, in url_patterns
    patterns = getattr(self.urlconf_module, "urlpatterns", self.urlconf_module)
  File "/projects/Python/Django/guestbook/venv/lib/python3.6/site-packages/django/utils/functional.py", line 80, in __get__
    res = instance.__dict__[self.name] = self.func(instance)
  File "/projects/Python/Django/guestbook/venv/lib/python3.6/site-packages/django/urls/resolvers.py", line 572, in urlconf_module
    return import_module(self.urlconf_name)
  File "/projects/Python/Django/guestbook/venv/lib/python3.6/importlib/__init__.py", line 126, in import_module
    return _bootstrap._gcd_import(name[level:], package, level)
  File "<frozen importlib._bootstrap>", line 994, in _gcd_import
  File "<frozen importlib._bootstrap>", line 971, in _find_and_load
  File "<frozen importlib._bootstrap>", line 955, in _find_and_load_unlocked
  File "<frozen importlib._bootstrap>", line 665, in _load_unlocked
  File "<frozen importlib._bootstrap_external>", line 678, in exec_module
  File "<frozen importlib._bootstrap>", line 219, in _call_with_frames_removed
  File "/projects/Python/Django/guestbook/main/main/urls.py", line 23, in <module>
    from guest.views import SignUpView
  File "/projects/Python/Django/guestbook/main/guest/views.py", line 5, in <module>
    from .forms import StudentSignUpForm
  File "/projects/Python/Django/guestbook/main/guest/forms.py", line 23, in <module>
    class StudentSignUpForm(UserCreationForm):
  File "/projects/Python/Django/guestbook/main/guest/forms.py", line 27, in StudentSignUpForm
    required=True
TypeError: __init__() missing 1 required positional argument: 'queryset'

/projects/Python/Django/guestbook/main/guest/forms.py changed, reloading.
Performing system checks...

Exception in thread django-main-thread:
Traceback (most recent call last):
  File "/usr/lib/python3.6/threading.py", line 916, in _bootstrap_inner
    self.run()
  File "/usr/lib/python3.6/threading.py", line 864, in run
    self._target(*self._args, **self._kwargs)
  File "/projects/Python/Django/guestbook/venv/lib/python3.6/site-packages/django/utils/autoreload.py", line 54, in wrapper
    fn(*args, **kwargs)
  File "/projects/Python/Django/guestbook/venv/lib/python3.6/site-packages/django/core/management/commands/runserver.py", line 117, in inner_run
    self.check(display_num_errors=True)
  File "/projects/Python/Django/guestbook/venv/lib/python3.6/site-packages/django/core/management/base.py", line 390, in check
    include_deployment_checks=include_deployment_checks,
  File "/projects/Python/Django/guestbook/venv/lib/python3.6/site-packages/django/core/management/base.py", line 377, in _run_checks
    return checks.run_checks(**kwargs)
  File "/projects/Python/Django/guestbook/venv/lib/python3.6/site-packages/django/core/checks/registry.py", line 72, in run_checks
    new_errors = check(app_configs=app_configs)
  File "/projects/Python/Django/guestbook/venv/lib/python3.6/site-packages/django/core/checks/urls.py", line 13, in check_url_config
    return check_resolver(resolver)
  File "/projects/Python/Django/guestbook/venv/lib/python3.6/site-packages/django/core/checks/urls.py", line 23, in check_resolver
    return check_method()
  File "/projects/Python/Django/guestbook/venv/lib/python3.6/site-packages/django/urls/resolvers.py", line 398, in check
    for pattern in self.url_patterns:
  File "/projects/Python/Django/guestbook/venv/lib/python3.6/site-packages/django/utils/functional.py", line 80, in __get__
    res = instance.__dict__[self.name] = self.func(instance)
  File "/projects/Python/Django/guestbook/venv/lib/python3.6/site-packages/django/urls/resolvers.py", line 579, in url_patterns
    patterns = getattr(self.urlconf_module, "urlpatterns", self.urlconf_module)
  File "/projects/Python/Django/guestbook/venv/lib/python3.6/site-packages/django/utils/functional.py", line 80, in __get__
    res = instance.__dict__[self.name] = self.func(instance)
  File "/projects/Python/Django/guestbook/venv/lib/python3.6/site-packages/django/urls/resolvers.py", line 572, in urlconf_module
    return import_module(self.urlconf_name)
  File "/projects/Python/Django/guestbook/venv/lib/python3.6/importlib/__init__.py", line 126, in import_module
    return _bootstrap._gcd_import(name[level:], package, level)
  File "<frozen importlib._bootstrap>", line 994, in _gcd_import
  File "<frozen importlib._bootstrap>", line 971, in _find_and_load
  File "<frozen importlib._bootstrap>", line 955, in _find_and_load_unlocked
  File "<frozen importlib._bootstrap>", line 665, in _load_unlocked
  File "<frozen importlib._bootstrap_external>", line 678, in exec_module
  File "<frozen importlib._bootstrap>", line 219, in _call_with_frames_removed
  File "/projects/Python/Django/guestbook/main/main/urls.py", line 23, in <module>
    from guest.views import SignUpView
  File "/projects/Python/Django/guestbook/main/guest/views.py", line 5, in <module>
    from .forms import StudentSignUpForm
  File "/projects/Python/Django/guestbook/main/guest/forms.py", line 23, in <module>
    class StudentSignUpForm(UserCreationForm):
  File "/projects/Python/Django/guestbook/main/guest/forms.py", line 27, in StudentSignUpForm
    required=True
TypeError: __init__() missing 1 required positional argument: 'queryset'

/projects/Python/Django/guestbook/main/guest/forms.py changed, reloading.
Performing system checks...

Watching for file changes with StatReloader
Watching for file changes with StatReloader
Watching for file changes with StatReloader
Exception in thread django-main-thread:
Traceback (most recent call last):
  File "/usr/lib/python3.6/threading.py", line 916, in _bootstrap_inner
    self.run()
  File "/usr/lib/python3.6/threading.py", line 864, in run
    self._target(*self._args, **self._kwargs)
  File "/projects/Python/Django/guestbook/venv/lib/python3.6/site-packages/django/utils/autoreload.py", line 54, in wrapper
    fn(*args, **kwargs)
  File "/projects/Python/Django/guestbook/venv/lib/python3.6/site-packages/django/core/management/commands/runserver.py", line 117, in inner_run
    self.check(display_num_errors=True)
  File "/projects/Python/Django/guestbook/venv/lib/python3.6/site-packages/django/core/management/base.py", line 390, in check
    include_deployment_checks=include_deployment_checks,
  File "/projects/Python/Django/guestbook/venv/lib/python3.6/site-packages/django/core/management/base.py", line 377, in _run_checks
    return checks.run_checks(**kwargs)
  File "/projects/Python/Django/guestbook/venv/lib/python3.6/site-packages/django/core/checks/registry.py", line 72, in run_checks
    new_errors = check(app_configs=app_configs)
  File "/projects/Python/Django/guestbook/venv/lib/python3.6/site-packages/django/core/checks/urls.py", line 13, in check_url_config
    return check_resolver(resolver)
  File "/projects/Python/Django/guestbook/venv/lib/python3.6/site-packages/django/core/checks/urls.py", line 23, in check_resolver
    return check_method()
  File "/projects/Python/Django/guestbook/venv/lib/python3.6/site-packages/django/urls/resolvers.py", line 398, in check
    for pattern in self.url_patterns:
  File "/projects/Python/Django/guestbook/venv/lib/python3.6/site-packages/django/utils/functional.py", line 80, in __get__
    res = instance.__dict__[self.name] = self.func(instance)
  File "/projects/Python/Django/guestbook/venv/lib/python3.6/site-packages/django/urls/resolvers.py", line 579, in url_patterns
    patterns = getattr(self.urlconf_module, "urlpatterns", self.urlconf_module)
  File "/projects/Python/Django/guestbook/venv/lib/python3.6/site-packages/django/utils/functional.py", line 80, in __get__
    res = instance.__dict__[self.name] = self.func(instance)
  File "/projects/Python/Django/guestbook/venv/lib/python3.6/site-packages/django/urls/resolvers.py", line 572, in urlconf_module
    return import_module(self.urlconf_name)
  File "/projects/Python/Django/guestbook/venv/lib/python3.6/importlib/__init__.py", line 126, in import_module
    return _bootstrap._gcd_import(name[level:], package, level)
  File "<frozen importlib._bootstrap>", line 994, in _gcd_import
  File "<frozen importlib._bootstrap>", line 971, in _find_and_load
  File "<frozen importlib._bootstrap>", line 955, in _find_and_load_unlocked
  File "<frozen importlib._bootstrap>", line 665, in _load_unlocked
  File "<frozen importlib._bootstrap_external>", line 678, in exec_module
  File "<frozen importlib._bootstrap>", line 219, in _call_with_frames_removed
  File "/projects/Python/Django/guestbook/main/main/urls.py", line 23, in <module>
    from guest.views import SignUpView
  File "/projects/Python/Django/guestbook/main/guest/views.py", line 5, in <module>
    from .forms import StudentSignUpForm
  File "/projects/Python/Django/guestbook/main/guest/forms.py", line 23, in <module>
    class StudentSignUpForm(UserCreationForm):
  File "/projects/Python/Django/guestbook/main/guest/forms.py", line 25, in StudentSignUpForm
    queryset=Subject.objects.all(),
NameError: name 'Subject' is not defined

/projects/Python/Django/guestbook/main/guest/forms.py changed, reloading.
Performing system checks...

Watching for file changes with StatReloader
Exception in thread django-main-thread:
Traceback (most recent call last):
  File "/usr/lib/python3.6/threading.py", line 916, in _bootstrap_inner
    self.run()
  File "/usr/lib/python3.6/threading.py", line 864, in run
    self._target(*self._args, **self._kwargs)
  File "/projects/Python/Django/guestbook/venv/lib/python3.6/site-packages/django/utils/autoreload.py", line 54, in wrapper
    fn(*args, **kwargs)
  File "/projects/Python/Django/guestbook/venv/lib/python3.6/site-packages/django/core/management/commands/runserver.py", line 117, in inner_run
    self.check(display_num_errors=True)
  File "/projects/Python/Django/guestbook/venv/lib/python3.6/site-packages/django/core/management/base.py", line 390, in check
    include_deployment_checks=include_deployment_checks,
  File "/projects/Python/Django/guestbook/venv/lib/python3.6/site-packages/django/core/management/base.py", line 377, in _run_checks
    return checks.run_checks(**kwargs)
  File "/projects/Python/Django/guestbook/venv/lib/python3.6/site-packages/django/core/checks/registry.py", line 72, in run_checks
    new_errors = check(app_configs=app_configs)
  File "/projects/Python/Django/guestbook/venv/lib/python3.6/site-packages/django/core/checks/urls.py", line 13, in check_url_config
    return check_resolver(resolver)
  File "/projects/Python/Django/guestbook/venv/lib/python3.6/site-packages/django/core/checks/urls.py", line 23, in check_resolver
    return check_method()
  File "/projects/Python/Django/guestbook/venv/lib/python3.6/site-packages/django/urls/resolvers.py", line 398, in check
    for pattern in self.url_patterns:
  File "/projects/Python/Django/guestbook/venv/lib/python3.6/site-packages/django/utils/functional.py", line 80, in __get__
    res = instance.__dict__[self.name] = self.func(instance)
  File "/projects/Python/Django/guestbook/venv/lib/python3.6/site-packages/django/urls/resolvers.py", line 579, in url_patterns
    patterns = getattr(self.urlconf_module, "urlpatterns", self.urlconf_module)
  File "/projects/Python/Django/guestbook/venv/lib/python3.6/site-packages/django/utils/functional.py", line 80, in __get__
    res = instance.__dict__[self.name] = self.func(instance)
  File "/projects/Python/Django/guestbook/venv/lib/python3.6/site-packages/django/urls/resolvers.py", line 572, in urlconf_module
    return import_module(self.urlconf_name)
  File "/projects/Python/Django/guestbook/venv/lib/python3.6/importlib/__init__.py", line 126, in import_module
    return _bootstrap._gcd_import(name[level:], package, level)
  File "<frozen importlib._bootstrap>", line 994, in _gcd_import
  File "<frozen importlib._bootstrap>", line 971, in _find_and_load
  File "<frozen importlib._bootstrap>", line 955, in _find_and_load_unlocked
  File "<frozen importlib._bootstrap>", line 665, in _load_unlocked
  File "<frozen importlib._bootstrap_external>", line 678, in exec_module
  File "<frozen importlib._bootstrap>", line 219, in _call_with_frames_removed
  File "/projects/Python/Django/guestbook/main/main/urls.py", line 23, in <module>
    from guest.views import SignUpView
  File "/projects/Python/Django/guestbook/main/guest/views.py", line 5, in <module>
    from .forms import StudentSignUpForm
  File "/projects/Python/Django/guestbook/main/guest/forms.py", line 23, in <module>
    class StudentSignUpForm(UserCreationForm):
  File "/projects/Python/Django/guestbook/main/guest/forms.py", line 25, in StudentSignUpForm
    queryset=Subject.objects.all(),
NameError: name 'Subject' is not defined

/projects/Python/Django/guestbook/main/guest/forms.py changed, reloading.
Performing system checks...

Exception in thread django-main-thread:
Traceback (most recent call last):
  File "/usr/lib/python3.6/threading.py", line 916, in _bootstrap_inner
    self.run()
  File "/usr/lib/python3.6/threading.py", line 864, in run
    self._target(*self._args, **self._kwargs)
  File "/projects/Python/Django/guestbook/venv/lib/python3.6/site-packages/django/utils/autoreload.py", line 54, in wrapper
    fn(*args, **kwargs)
  File "/projects/Python/Django/guestbook/venv/lib/python3.6/site-packages/django/core/management/commands/runserver.py", line 117, in inner_run
    self.check(display_num_errors=True)
  File "/projects/Python/Django/guestbook/venv/lib/python3.6/site-packages/django/core/management/base.py", line 390, in check
    include_deployment_checks=include_deployment_checks,
  File "/projects/Python/Django/guestbook/venv/lib/python3.6/site-packages/django/core/management/base.py", line 377, in _run_checks
    return checks.run_checks(**kwargs)
  File "/projects/Python/Django/guestbook/venv/lib/python3.6/site-packages/django/core/checks/registry.py", line 72, in run_checks
    new_errors = check(app_configs=app_configs)
  File "/projects/Python/Django/guestbook/venv/lib/python3.6/site-packages/django/core/checks/urls.py", line 13, in check_url_config
    return check_resolver(resolver)
  File "/projects/Python/Django/guestbook/venv/lib/python3.6/site-packages/django/core/checks/urls.py", line 23, in check_resolver
    return check_method()
  File "/projects/Python/Django/guestbook/venv/lib/python3.6/site-packages/django/urls/resolvers.py", line 398, in check
    for pattern in self.url_patterns:
  File "/projects/Python/Django/guestbook/venv/lib/python3.6/site-packages/django/utils/functional.py", line 80, in __get__
    res = instance.__dict__[self.name] = self.func(instance)
  File "/projects/Python/Django/guestbook/venv/lib/python3.6/site-packages/django/urls/resolvers.py", line 579, in url_patterns
    patterns = getattr(self.urlconf_module, "urlpatterns", self.urlconf_module)
  File "/projects/Python/Django/guestbook/venv/lib/python3.6/site-packages/django/utils/functional.py", line 80, in __get__
    res = instance.__dict__[self.name] = self.func(instance)
  File "/projects/Python/Django/guestbook/venv/lib/python3.6/site-packages/django/urls/resolvers.py", line 572, in urlconf_module
    return import_module(self.urlconf_name)
  File "/projects/Python/Django/guestbook/venv/lib/python3.6/importlib/__init__.py", line 126, in import_module
    return _bootstrap._gcd_import(name[level:], package, level)
  File "<frozen importlib._bootstrap>", line 994, in _gcd_import
  File "<frozen importlib._bootstrap>", line 971, in _find_and_load
  File "<frozen importlib._bootstrap>", line 955, in _find_and_load_unlocked
  File "<frozen importlib._bootstrap>", line 665, in _load_unlocked
  File "<frozen importlib._bootstrap_external>", line 678, in exec_module
  File "<frozen importlib._bootstrap>", line 219, in _call_with_frames_removed
  File "/projects/Python/Django/guestbook/main/main/urls.py", line 23, in <module>
    from guest.views import SignUpView
  File "/projects/Python/Django/guestbook/main/guest/views.py", line 5, in <module>
    from .forms import StudentSignUpForm
  File "/projects/Python/Django/guestbook/main/guest/forms.py", line 23, in <module>
    class StudentSignUpForm(UserCreationForm):
  File "/projects/Python/Django/guestbook/main/guest/forms.py", line 25, in StudentSignUpForm
    queryset=Subject.objects.all(),
NameError: name 'Subject' is not defined

/projects/Python/Django/guestbook/main/guest/forms.py changed, reloading.
Performing system checks...

Watching for file changes with StatReloader
Watching for file changes with StatReloader
/projects/Python/Django/guestbook/main/guest/forms.py changed, reloading.
Performing system checks...

System check identified no issues (0 silenced).
/projects/Python/Django/guestbook/main/guest/forms.py changed, reloading.
Performing system checks...

System check identified no issues (0 silenced).
Watching for file changes with StatReloader
/projects/Python/Django/guestbook/main/guest/forms.py changed, reloading.
Performing system checks...

System check identified no issues (0 silenced).
Watching for file changes with StatReloader
Watching for file changes with StatReloader
Exception in thread django-main-thread:
Traceback (most recent call last):
  File "/usr/lib/python3.6/threading.py", line 916, in _bootstrap_inner
    self.run()
  File "/usr/lib/python3.6/threading.py", line 864, in run
    self._target(*self._args, **self._kwargs)
  File "/projects/Python/Django/guestbook/venv/lib/python3.6/site-packages/django/utils/autoreload.py", line 54, in wrapper
    fn(*args, **kwargs)
  File "/projects/Python/Django/guestbook/venv/lib/python3.6/site-packages/django/core/management/commands/runserver.py", line 117, in inner_run
    self.check(display_num_errors=True)
  File "/projects/Python/Django/guestbook/venv/lib/python3.6/site-packages/django/core/management/base.py", line 390, in check
    include_deployment_checks=include_deployment_checks,
  File "/projects/Python/Django/guestbook/venv/lib/python3.6/site-packages/django/core/management/base.py", line 377, in _run_checks
    return checks.run_checks(**kwargs)
  File "/projects/Python/Django/guestbook/venv/lib/python3.6/site-packages/django/core/checks/registry.py", line 72, in run_checks
    new_errors = check(app_configs=app_configs)
  File "/projects/Python/Django/guestbook/venv/lib/python3.6/site-packages/django/core/checks/urls.py", line 13, in check_url_config
    return check_resolver(resolver)
  File "/projects/Python/Django/guestbook/venv/lib/python3.6/site-packages/django/core/checks/urls.py", line 23, in check_resolver
    return check_method()
  File "/projects/Python/Django/guestbook/venv/lib/python3.6/site-packages/django/urls/resolvers.py", line 398, in check
    for pattern in self.url_patterns:
  File "/projects/Python/Django/guestbook/venv/lib/python3.6/site-packages/django/utils/functional.py", line 80, in __get__
    res = instance.__dict__[self.name] = self.func(instance)
  File "/projects/Python/Django/guestbook/venv/lib/python3.6/site-packages/django/urls/resolvers.py", line 579, in url_patterns
    patterns = getattr(self.urlconf_module, "urlpatterns", self.urlconf_module)
  File "/projects/Python/Django/guestbook/venv/lib/python3.6/site-packages/django/utils/functional.py", line 80, in __get__
    res = instance.__dict__[self.name] = self.func(instance)
  File "/projects/Python/Django/guestbook/venv/lib/python3.6/site-packages/django/urls/resolvers.py", line 572, in urlconf_module
    return import_module(self.urlconf_name)
  File "/projects/Python/Django/guestbook/venv/lib/python3.6/importlib/__init__.py", line 126, in import_module
    return _bootstrap._gcd_import(name[level:], package, level)
  File "<frozen importlib._bootstrap>", line 994, in _gcd_import
  File "<frozen importlib._bootstrap>", line 971, in _find_and_load
  File "<frozen importlib._bootstrap>", line 955, in _find_and_load_unlocked
  File "<frozen importlib._bootstrap>", line 665, in _load_unlocked
  File "<frozen importlib._bootstrap_external>", line 678, in exec_module
  File "<frozen importlib._bootstrap>", line 219, in _call_with_frames_removed
  File "/projects/Python/Django/guestbook/main/main/urls.py", line 23, in <module>
    from guest.views import SignUpView
  File "/projects/Python/Django/guestbook/main/guest/views.py", line 5, in <module>
    from .forms import StudentSignUpForm
  File "/projects/Python/Django/guestbook/main/guest/forms.py", line 25
    queryset=.objects.all(),
             ^
SyntaxError: invalid syntax

/projects/Python/Django/guestbook/main/guest/forms.py changed, reloading.
Performing system checks...

Exception in thread django-main-thread:
Traceback (most recent call last):
  File "/usr/lib/python3.6/threading.py", line 916, in _bootstrap_inner
    self.run()
  File "/usr/lib/python3.6/threading.py", line 864, in run
    self._target(*self._args, **self._kwargs)
  File "/projects/Python/Django/guestbook/venv/lib/python3.6/site-packages/django/utils/autoreload.py", line 54, in wrapper
    fn(*args, **kwargs)
  File "/projects/Python/Django/guestbook/venv/lib/python3.6/site-packages/django/core/management/commands/runserver.py", line 117, in inner_run
    self.check(display_num_errors=True)
  File "/projects/Python/Django/guestbook/venv/lib/python3.6/site-packages/django/core/management/base.py", line 390, in check
    include_deployment_checks=include_deployment_checks,
  File "/projects/Python/Django/guestbook/venv/lib/python3.6/site-packages/django/core/management/base.py", line 377, in _run_checks
    return checks.run_checks(**kwargs)
  File "/projects/Python/Django/guestbook/venv/lib/python3.6/site-packages/django/core/checks/registry.py", line 72, in run_checks
    new_errors = check(app_configs=app_configs)
  File "/projects/Python/Django/guestbook/venv/lib/python3.6/site-packages/django/core/checks/urls.py", line 13, in check_url_config
    return check_resolver(resolver)
  File "/projects/Python/Django/guestbook/venv/lib/python3.6/site-packages/django/core/checks/urls.py", line 23, in check_resolver
    return check_method()
  File "/projects/Python/Django/guestbook/venv/lib/python3.6/site-packages/django/urls/resolvers.py", line 398, in check
    for pattern in self.url_patterns:
  File "/projects/Python/Django/guestbook/venv/lib/python3.6/site-packages/django/utils/functional.py", line 80, in __get__
    res = instance.__dict__[self.name] = self.func(instance)
  File "/projects/Python/Django/guestbook/venv/lib/python3.6/site-packages/django/urls/resolvers.py", line 579, in url_patterns
    patterns = getattr(self.urlconf_module, "urlpatterns", self.urlconf_module)
  File "/projects/Python/Django/guestbook/venv/lib/python3.6/site-packages/django/utils/functional.py", line 80, in __get__
    res = instance.__dict__[self.name] = self.func(instance)
  File "/projects/Python/Django/guestbook/venv/lib/python3.6/site-packages/django/urls/resolvers.py", line 572, in urlconf_module
    return import_module(self.urlconf_name)
  File "/projects/Python/Django/guestbook/venv/lib/python3.6/importlib/__init__.py", line 126, in import_module
    return _bootstrap._gcd_import(name[level:], package, level)
  File "<frozen importlib._bootstrap>", line 994, in _gcd_import
  File "<frozen importlib._bootstrap>", line 971, in _find_and_load
  File "<frozen importlib._bootstrap>", line 955, in _find_and_load_unlocked
  File "<frozen importlib._bootstrap>", line 665, in _load_unlocked
  File "<frozen importlib._bootstrap_external>", line 678, in exec_module
  File "<frozen importlib._bootstrap>", line 219, in _call_with_frames_removed
  File "/projects/Python/Django/guestbook/main/main/urls.py", line 23, in <module>
    from guest.views import SignUpView
  File "/projects/Python/Django/guestbook/main/guest/views.py", line 5, in <module>
    from .forms import StudentSignUpForm
  File "/projects/Python/Django/guestbook/main/guest/forms.py", line 25
    queryset=.objects.all(),
             ^
SyntaxError: invalid syntax

/projects/Python/Django/guestbook/main/guest/forms.py changed, reloading.
Performing system checks...

Watching for file changes with StatReloader
Watching for file changes with StatReloader
Exception in thread django-main-thread:
Traceback (most recent call last):
  File "/usr/lib/python3.6/threading.py", line 916, in _bootstrap_inner
    self.run()
  File "/usr/lib/python3.6/threading.py", line 864, in run
    self._target(*self._args, **self._kwargs)
  File "/projects/Python/Django/guestbook/venv/lib/python3.6/site-packages/django/utils/autoreload.py", line 54, in wrapper
    fn(*args, **kwargs)
  File "/projects/Python/Django/guestbook/venv/lib/python3.6/site-packages/django/core/management/commands/runserver.py", line 117, in inner_run
    self.check(display_num_errors=True)
  File "/projects/Python/Django/guestbook/venv/lib/python3.6/site-packages/django/core/management/base.py", line 390, in check
    include_deployment_checks=include_deployment_checks,
  File "/projects/Python/Django/guestbook/venv/lib/python3.6/site-packages/django/core/management/base.py", line 377, in _run_checks
    return checks.run_checks(**kwargs)
  File "/projects/Python/Django/guestbook/venv/lib/python3.6/site-packages/django/core/checks/registry.py", line 72, in run_checks
    new_errors = check(app_configs=app_configs)
  File "/projects/Python/Django/guestbook/venv/lib/python3.6/site-packages/django/core/checks/urls.py", line 13, in check_url_config
    return check_resolver(resolver)
  File "/projects/Python/Django/guestbook/venv/lib/python3.6/site-packages/django/core/checks/urls.py", line 23, in check_resolver
    return check_method()
  File "/projects/Python/Django/guestbook/venv/lib/python3.6/site-packages/django/urls/resolvers.py", line 398, in check
    for pattern in self.url_patterns:
  File "/projects/Python/Django/guestbook/venv/lib/python3.6/site-packages/django/utils/functional.py", line 80, in __get__
    res = instance.__dict__[self.name] = self.func(instance)
  File "/projects/Python/Django/guestbook/venv/lib/python3.6/site-packages/django/urls/resolvers.py", line 579, in url_patterns
    patterns = getattr(self.urlconf_module, "urlpatterns", self.urlconf_module)
  File "/projects/Python/Django/guestbook/venv/lib/python3.6/site-packages/django/utils/functional.py", line 80, in __get__
    res = instance.__dict__[self.name] = self.func(instance)
  File "/projects/Python/Django/guestbook/venv/lib/python3.6/site-packages/django/urls/resolvers.py", line 572, in urlconf_module
    return import_module(self.urlconf_name)
  File "/projects/Python/Django/guestbook/venv/lib/python3.6/importlib/__init__.py", line 126, in import_module
    return _bootstrap._gcd_import(name[level:], package, level)
  File "<frozen importlib._bootstrap>", line 994, in _gcd_import
  File "<frozen importlib._bootstrap>", line 971, in _find_and_load
  File "<frozen importlib._bootstrap>", line 955, in _find_and_load_unlocked
  File "<frozen importlib._bootstrap>", line 665, in _load_unlocked
  File "<frozen importlib._bootstrap_external>", line 678, in exec_module
  File "<frozen importlib._bootstrap>", line 219, in _call_with_frames_removed
  File "/projects/Python/Django/guestbook/main/main/urls.py", line 23, in <module>
    from guest.views import SignUpView
  File "/projects/Python/Django/guestbook/main/guest/views.py", line 5, in <module>
    from .forms import StudentSignUpForm
  File "/projects/Python/Django/guestbook/main/guest/forms.py", line 23, in <module>
    class StudentSignUpForm(UserCreationForm):
  File "/projects/Python/Django/guestbook/main/guest/forms.py", line 25, in StudentSignUpForm
    queryset=Subject.objects.all(),
NameError: name 'Subject' is not defined

/projects/Python/Django/guestbook/main/guest/forms.py changed, reloading.
Performing system checks...

Exception in thread django-main-thread:
Traceback (most recent call last):
  File "/usr/lib/python3.6/threading.py", line 916, in _bootstrap_inner
    self.run()
  File "/usr/lib/python3.6/threading.py", line 864, in run
    self._target(*self._args, **self._kwargs)
  File "/projects/Python/Django/guestbook/venv/lib/python3.6/site-packages/django/utils/autoreload.py", line 54, in wrapper
    fn(*args, **kwargs)
  File "/projects/Python/Django/guestbook/venv/lib/python3.6/site-packages/django/core/management/commands/runserver.py", line 117, in inner_run
    self.check(display_num_errors=True)
  File "/projects/Python/Django/guestbook/venv/lib/python3.6/site-packages/django/core/management/base.py", line 390, in check
    include_deployment_checks=include_deployment_checks,
  File "/projects/Python/Django/guestbook/venv/lib/python3.6/site-packages/django/core/management/base.py", line 377, in _run_checks
    return checks.run_checks(**kwargs)
  File "/projects/Python/Django/guestbook/venv/lib/python3.6/site-packages/django/core/checks/registry.py", line 72, in run_checks
    new_errors = check(app_configs=app_configs)
  File "/projects/Python/Django/guestbook/venv/lib/python3.6/site-packages/django/core/checks/urls.py", line 13, in check_url_config
    return check_resolver(resolver)
  File "/projects/Python/Django/guestbook/venv/lib/python3.6/site-packages/django/core/checks/urls.py", line 23, in check_resolver
    return check_method()
  File "/projects/Python/Django/guestbook/venv/lib/python3.6/site-packages/django/urls/resolvers.py", line 398, in check
    for pattern in self.url_patterns:
  File "/projects/Python/Django/guestbook/venv/lib/python3.6/site-packages/django/utils/functional.py", line 80, in __get__
    res = instance.__dict__[self.name] = self.func(instance)
  File "/projects/Python/Django/guestbook/venv/lib/python3.6/site-packages/django/urls/resolvers.py", line 579, in url_patterns
    patterns = getattr(self.urlconf_module, "urlpatterns", self.urlconf_module)
  File "/projects/Python/Django/guestbook/venv/lib/python3.6/site-packages/django/utils/functional.py", line 80, in __get__
    res = instance.__dict__[self.name] = self.func(instance)
  File "/projects/Python/Django/guestbook/venv/lib/python3.6/site-packages/django/urls/resolvers.py", line 572, in urlconf_module
    return import_module(self.urlconf_name)
  File "/projects/Python/Django/guestbook/venv/lib/python3.6/importlib/__init__.py", line 126, in import_module
    return _bootstrap._gcd_import(name[level:], package, level)
  File "<frozen importlib._bootstrap>", line 994, in _gcd_import
  File "<frozen importlib._bootstrap>", line 971, in _find_and_load
  File "<frozen importlib._bootstrap>", line 955, in _find_and_load_unlocked
  File "<frozen importlib._bootstrap>", line 665, in _load_unlocked
  File "<frozen importlib._bootstrap_external>", line 678, in exec_module
  File "<frozen importlib._bootstrap>", line 219, in _call_with_frames_removed
  File "/projects/Python/Django/guestbook/main/main/urls.py", line 23, in <module>
    from guest.views import SignUpView
  File "/projects/Python/Django/guestbook/main/guest/views.py", line 5, in <module>
    from .forms import StudentSignUpForm
  File "/projects/Python/Django/guestbook/main/guest/forms.py", line 23, in <module>
    class StudentSignUpForm(UserCreationForm):
  File "/projects/Python/Django/guestbook/main/guest/forms.py", line 25, in StudentSignUpForm
    queryset=Subject.objects.all(),
NameError: name 'Subject' is not defined

/projects/Python/Django/guestbook/main/guest/forms.py changed, reloading.
Performing system checks...

Exception in thread django-main-thread:
Traceback (most recent call last):
  File "/usr/lib/python3.6/threading.py", line 916, in _bootstrap_inner
    self.run()
  File "/usr/lib/python3.6/threading.py", line 864, in run
    self._target(*self._args, **self._kwargs)
  File "/projects/Python/Django/guestbook/venv/lib/python3.6/site-packages/django/utils/autoreload.py", line 54, in wrapper
    fn(*args, **kwargs)
  File "/projects/Python/Django/guestbook/venv/lib/python3.6/site-packages/django/core/management/commands/runserver.py", line 117, in inner_run
    self.check(display_num_errors=True)
  File "/projects/Python/Django/guestbook/venv/lib/python3.6/site-packages/django/core/management/base.py", line 390, in check
    include_deployment_checks=include_deployment_checks,
  File "/projects/Python/Django/guestbook/venv/lib/python3.6/site-packages/django/core/management/base.py", line 377, in _run_checks
    return checks.run_checks(**kwargs)
  File "/projects/Python/Django/guestbook/venv/lib/python3.6/site-packages/django/core/checks/registry.py", line 72, in run_checks
    new_errors = check(app_configs=app_configs)
  File "/projects/Python/Django/guestbook/venv/lib/python3.6/site-packages/django/core/checks/urls.py", line 13, in check_url_config
    return check_resolver(resolver)
  File "/projects/Python/Django/guestbook/venv/lib/python3.6/site-packages/django/core/checks/urls.py", line 23, in check_resolver
    return check_method()
  File "/projects/Python/Django/guestbook/venv/lib/python3.6/site-packages/django/urls/resolvers.py", line 398, in check
    for pattern in self.url_patterns:
  File "/projects/Python/Django/guestbook/venv/lib/python3.6/site-packages/django/utils/functional.py", line 80, in __get__
    res = instance.__dict__[self.name] = self.func(instance)
  File "/projects/Python/Django/guestbook/venv/lib/python3.6/site-packages/django/urls/resolvers.py", line 579, in url_patterns
    patterns = getattr(self.urlconf_module, "urlpatterns", self.urlconf_module)
  File "/projects/Python/Django/guestbook/venv/lib/python3.6/site-packages/django/utils/functional.py", line 80, in __get__
    res = instance.__dict__[self.name] = self.func(instance)
  File "/projects/Python/Django/guestbook/venv/lib/python3.6/site-packages/django/urls/resolvers.py", line 572, in urlconf_module
    return import_module(self.urlconf_name)
  File "/projects/Python/Django/guestbook/venv/lib/python3.6/importlib/__init__.py", line 126, in import_module
    return _bootstrap._gcd_import(name[level:], package, level)
  File "<frozen importlib._bootstrap>", line 994, in _gcd_import
  File "<frozen importlib._bootstrap>", line 971, in _find_and_load
  File "<frozen importlib._bootstrap>", line 955, in _find_and_load_unlocked
  File "<frozen importlib._bootstrap>", line 665, in _load_unlocked
  File "<frozen importlib._bootstrap_external>", line 678, in exec_module
  File "<frozen importlib._bootstrap>", line 219, in _call_with_frames_removed
  File "/projects/Python/Django/guestbook/main/main/urls.py", line 23, in <module>
    from guest.views import SignUpView
  File "/projects/Python/Django/guestbook/main/guest/views.py", line 5, in <module>
    from .forms import StudentSignUpForm
  File "/projects/Python/Django/guestbook/main/guest/forms.py", line 23, in <module>
    class StudentSignUpForm(UserCreationForm):
  File "/projects/Python/Django/guestbook/main/guest/forms.py", line 25, in StudentSignUpForm
    queryset=Subject.objects.all(),
NameError: name 'Subject' is not defined

/projects/Python/Django/guestbook/main/guest/forms.py changed, reloading.
Performing system checks...

Watching for file changes with StatReloader
Watching for file changes with StatReloader
Watching for file changes with StatReloader
Watching for file changes with StatReloader
Watching for file changes with StatReloader
Watching for file changes with StatReloader
